Workbook

Sheet mastered-10-26mar-dirty
A1: student | B1: third_party_level_id | C1: app | D1: date | E1: activity_units_attempted | F1: activity_units_correct | G1: level | H1: order
A2: Alessandra Green | B2: 3.2.FRAGMENT_OR_SENTENCE | C2: Alphawrite | D2: 45742 | E2: 38 | F2: 30 | G2: =LEFT(B2) -> 3 | H2: =VLOOKUP(B2,#REF!,5,FALSE) -> #REF!
A3: Arjun Caberwal | B3: 4.2.IDENTIFY_APPOSITIVES | C3: Alphawrite | D3: 45742 | E3: 19 | F3: 13 | G3: =LEFT(B3) -> 4 | H3: =VLOOKUP(B3,#REF!,5,FALSE) -> #REF!
A4: Arman Caberwal | B4: 4.2.WRITE_SENTENCE_ABOUT_PICTURE | C4: Alphawrite | D4: 45742 | E4: 12 | F4: 12 | G4: =LEFT(B4) -> 4 | H4: =VLOOKUP(B4,#REF!,5,FALSE) -> #REF!
A5: Arman Caberwal | B5: 4.2.WRITE_SENTENCE_TYPE | C5: Alphawrite | D5: 45742 | E5: 7 | F5: 7 | G5: =LEFT(B5) -> 4 | H5: =VLOOKUP(B5,#REF!,5,FALSE) -> #REF!
A6: Blake Flores | B6: 5.2.CHANGE_SENTENCE_TYPE | C6: Alphawrite | D6: 45742 | E6: 6 | F6: 2 | G6: =LEFT(B6) -> 5 | H6: =VLOOKUP(B6,#REF!,5,FALSE) -> #REF!
A7: Brady York | B7: 3.2.CHANGE_SENTENCE_TYPE | C7: Alphawrite | D7: 45742 | E7: 11 | F7: 5 | G7: =LEFT(B7) -> 3 | H7: =VLOOKUP(B7,#REF!,5,FALSE) -> #REF!
A8: Brady York | B8: 3.2.IDENTIFY_SENTENCE_TYPE | C8: Alphawrite | D8: 45742 | E8: 16 | F8: 14 | G8: =LEFT(B8) -> 3 | H8: =VLOOKUP(B8,#REF!,5,FALSE) -> #REF!
A9: David Paul | B9: 3.2.CHANGE_SENTENCE_TYPE | C9: Alphawrite | D9: 45742 | E9: 73 | F9: 44 | G9: =LEFT(B9) -> 3 | H9: =VLOOKUP(B9,#REF!,5,FALSE) -> #REF!
A10: David Paul | B10: 3.2.WRITE_SENTENCE_TYPE | C10: Alphawrite | D10: 45742 | E10: 4 | F10: 4 | G10: =LEFT(B10) -> 3 | H10: =VLOOKUP(B10,#REF!,5,FALSE) -> #REF!
A11: David Paul | B11: 4.2.FRAGMENT_OR_SENTENCE | C11: Alphawrite | D11: 45742 | E11: 2 | F11: 0 | G11: =LEFT(B11) -> 4 | H11: =VLOOKUP(B11,#REF!,5,FALSE) -> #REF!
A12: Elaina Robertson | B12: 4.2.UNSCRAMBLE_SENTENCES | C12: Alphawrite | D12: 45742 | E12: 13 | F12: 12 | G12: =LEFT(B12) -> 4 | H12: =VLOOKUP(B12,#REF!,5,FALSE) -> #REF!
A13: Evelyn Gabler | B13: 4.2.BASIC_CONJUNCTIONS | C13: Alphawrite | D13: 45742 | E13: 8 | F13: 8 | G13: =LEFT(B13) -> 4 | H13: =VLOOKUP(B13,#REF!,5,FALSE) -> #REF!
A14: Evelyn Gabler | B14: 4.2.KERNEL_EXPANSION | C14: Alphawrite | D14: 45742 | G14: =LEFT(B14) -> 4 | H14: =VLOOKUP(B14,#REF!,5,FALSE) -> #REF!
A15: Evelyn Gabler | B15: 5.2.FRAGMENT_OR_SENTENCE | C15: Alphawrite | D15: 45742 | G15: =LEFT(B15) -> 5 | H15: =VLOOKUP(B15,#REF!,5,FALSE) -> #REF!
A16: Hazel Salton | B16: 3.2.CHANGE_SENTENCE_TYPE | C16: Alphawrite | D16: 45742 | G16: =LEFT(B16) -> 3 | H16: =VLOOKUP(B16,#REF!,5,FALSE) -> #REF!
A17: Hazel Salton | B17: 3.2.UNSCRAMBLE_SENTENCES | C17: Alphawrite | D17: 45742 | E17: 11 | F17: 7 | G17: =LEFT(B17) -> 3 | H17: =VLOOKUP(B17,#REF!,5,FALSE) -> #REF!
A18: Hazel Salton | B18: 3.2.WRITE_SENTENCE_ABOUT_PICTURE | C18: Alphawrite | D18: 45742 | E18: 15 | F18: 11 | G18: =LEFT(B18) -> 3 | H18: =VLOOKUP(B18,#REF!,5,FALSE) -> #REF!
A19: Hazel Salton | B19: 4.2.FRAGMENT_OR_SENTENCE | C19: Alphawrite | D19: 45742 | G19: =LEFT(B19) -> 4 | H19: =VLOOKUP(B19,#REF!,5,FALSE) -> #REF!
A20: Helio Ortiz | B20: 3.2.FRAGMENT_OR_SENTENCE | C20: Alphawrite | D20: 45742 | E20: 49 | F20: 20 | G20: =LEFT(B20) -> 3 | H20: =VLOOKUP(B20,#REF!,5,FALSE) -> #REF!
A21: Ian Mentgen | B21: 3.2.UNSCRAMBLE_SENTENCES | C21: Alphawrite | D21: 45742 | G21: =LEFT(B21) -> 3 | H21: =VLOOKUP(B21,#REF!,5,FALSE) -> #REF!
A22: Ian Mentgen | B22: 3.2.WRITE_SENTENCE_TYPE | C22: Alphawrite | D22: 45742 | E22: 16 | F22: 14 | G22: =LEFT(B22) -> 3 | H22: =VLOOKUP(B22,#REF!,5,FALSE) -> #REF!
A23: Jaxon Siers | B23: 3.2.IDENTIFY_APPOSITIVES | C23: Alphawrite | D23: 45742 | E23: 26 | F23: 16 | G23: =LEFT(B23) -> 3 | H23: =VLOOKUP(B23,#REF!,5,FALSE) -> #REF!
A24: Jaxon Siers | B24: 3.2.WRITE_APPOSITIVES | C24: Alphawrite | D24: 45742 | E24: 26 | F24: 20 | G24: =LEFT(B24) -> 3 | H24: =VLOOKUP(B24,#REF!,5,FALSE) -> #REF!
A25: Jaxon Siers | B25: 4.2.FRAGMENT_OR_SENTENCE | C25: Alphawrite | D25: 45742 | G25: =LEFT(B25) -> 4 | H25: =VLOOKUP(B25,#REF!,5,FALSE) -> #REF!
A26: Lavender Marrero | B26: 4.2.CHANGE_SENTENCE_TYPE | C26: Alphawrite | D26: 45742 | E26: 6 | F26: 2 | G26: =LEFT(B26) -> 4 | H26: =VLOOKUP(B26,#REF!,5,FALSE) -> #REF!
A27: Lily Gray | B27: 5.2.FRAGMENT_OR_SENTENCE | C27: Alphawrite | D27: 45742 | G27: =LEFT(B27) -> 5 | H27: =VLOOKUP(B27,#REF!,5,FALSE) -> #REF!
A28: Logan Campbell | B28: 4.2.COMBINE_SENTENCES | C28: Alphawrite | D28: 45742 | G28: =LEFT(B28) -> 4 | H28: =VLOOKUP(B28,#REF!,5,FALSE) -> #REF!
A29: Marcus Fuentes | B29: 3.2.WRITE_APPOSITIVES | C29: Alphawrite | D29: 45742 | E29: 17 | F29: 13 | G29: =LEFT(B29) -> 3 | H29: =VLOOKUP(B29,#REF!,5,FALSE) -> #REF!
A30: Max Vaughan | B30: 3.2.UNSCRAMBLE_SENTENCES | C30: Alphawrite | D30: 45742 | E30: 12 | F30: 12 | G30: =LEFT(B30) -> 3 | H30: =VLOOKUP(B30,#REF!,5,FALSE) -> #REF!
A31: Mila Atamas | B31: 5.2.FRAGMENT_OR_SENTENCE | C31: Alphawrite | D31: 45742 | E31: 20 | F31: 16 | G31: =LEFT(B31) -> 5 | H31: =VLOOKUP(B31,#REF!,5,FALSE) -> #REF!
A32: Omar Ibarra | B32: 4.2.FRAGMENT_OR_SENTENCE | C32: Alphawrite | D32: 45742 | E32: 10 | F32: 4 | G32: =LEFT(B32) -> 4 | H32: =VLOOKUP(B32,#REF!,5,FALSE) -> #REF!
A33: Orion Campbell | B33: 5.2.CHANGE_SENTENCE_TYPE | C33: Alphawrite | D33: 45742 | E33: 2 | F33: 0 | G33: =LEFT(B33) -> 5 | H33: =VLOOKUP(B33,#REF!,5,FALSE) -> #REF!
A34: Orion Campbell | B34: 5.2.FRAGMENT_OR_SENTENCE | C34: Alphawrite | D34: 45742 | G34: =LEFT(B34) -> 5 | H34: =VLOOKUP(B34,#REF!,5,FALSE) -> #REF!
A35: Raegan Middleton | B35: 3.2.UNSCRAMBLE_SENTENCES | C35: Alphawrite | D35: 45742 | E35: 28 | F35: 26 | G35: =LEFT(B35) -> 3 | H35: =VLOOKUP(B35,#REF!,5,FALSE) -> #REF!
A36: Ramsey Levin | B36: 4.2.BASIC_CONJUNCTIONS | C36: Alphawrite | D36: 45742 | G36: =LEFT(B36) -> 4 | H36: =VLOOKUP(B36,#REF!,5,FALSE) -> #REF!
A37: Ramsey Levin | B37: 4.2.COMBINE_SENTENCES | C37: Alphawrite | D37: 45742 | G37: =LEFT(B37) -> 4 | H37: =VLOOKUP(B37,#REF!,5,FALSE) -> #REF!
A38: Ramsey Levin | B38: 4.2.WRITE_APPOSITIVES | C38: Alphawrite | D38: 45742 | E38: 4 | F38: 2 | G38: =LEFT(B38) -> 4 | H38: =VLOOKUP(B38,#REF!,5,FALSE) -> #REF!
A39: Ramsey Levin | B39: 4.2.WRITE_SENTENCE_TYPE | C39: Alphawrite | D39: 45742 | G39: =LEFT(B39) -> 4 | H39: =VLOOKUP(B39,#REF!,5,FALSE) -> #REF!
A40: Rocco Benetti | B40: 5.2.COMBINE_SENTENCES | C40: Alphawrite | D40: 45742 | E40: 2 | F40: 0 | G40: =LEFT(B40) -> 5 | H40: =VLOOKUP(B40,#REF!,5,FALSE) -> #REF!
...

Sheet student-list-vs-mastered-lesson
A1: =IFERROR(__xludf.DUMMYFUNCTION("importrange(""https://docs.google.com/spreadsheets/d/1wBLO22hSTrKfDDXCrHIEZ1WCYIgyc-J2krKizrpx500/edit?gid=0#gid=0"",""Master!P:Q"")"),"Full Name") -> Full Name | B1: =IFERROR(__xludf.DUMMYFUNCTION("""COMPUTED_VALUE"""),"Level") -> Level | C1: Mastered a Lesson? | D1: Lessons Mastered
A2: =IFERROR(__xludf.DUMMYFUNCTION("""COMPUTED_VALUE"""),"Atlas Kloiber") -> Atlas Kloiber | B2: =IFERROR(__xludf.DUMMYFUNCTION("""COMPUTED_VALUE"""),"L2") -> L2 | C2: =IF(D2>0,"Yes","No") -> No | D2: 0
A3: =IFERROR(__xludf.DUMMYFUNCTION("""COMPUTED_VALUE"""),"Scotty Noel") -> Scotty Noel | B3: =IFERROR(__xludf.DUMMYFUNCTION("""COMPUTED_VALUE"""),"L2") -> L2 | C3: =IF(D3>0,"Yes","No") -> No | D3: 0
A4: =IFERROR(__xludf.DUMMYFUNCTION("""COMPUTED_VALUE"""),"Gray Duffy") -> Gray Duffy | B4: =IFERROR(__xludf.DUMMYFUNCTION("""COMPUTED_VALUE"""),"L2") -> L2 | C4: =IF(D4>0,"Yes","No") -> No | D4: 0
A5: =IFERROR(__xludf.DUMMYFUNCTION("""COMPUTED_VALUE"""),"Knox Martin Wheeler") -> Knox Martin Wheeler | B5: =IFERROR(__xludf.DUMMYFUNCTION("""COMPUTED_VALUE"""),"L2") -> L2 | C5: =IF(D5>0,"Yes","No") -> No | D5: 0
A6: =IFERROR(__xludf.DUMMYFUNCTION("""COMPUTED_VALUE"""),"Roman-Parker Davis") -> Roman-Parker Davis | B6: =IFERROR(__xludf.DUMMYFUNCTION("""COMPUTED_VALUE"""),"L2") -> L2 | C6: =IF(D6>0,"Yes","No") -> No | D6: 0
A7: =IFERROR(__xludf.DUMMYFUNCTION("""COMPUTED_VALUE"""),"Amelia Catherine Lucas") -> Amelia Catherine Lucas | B7: =IFERROR(__xludf.DUMMYFUNCTION("""COMPUTED_VALUE"""),"MS") -> MS | C7: =IF(D7>0,"Yes","No") -> No | D7: 0
A8: =IFERROR(__xludf.DUMMYFUNCTION("""COMPUTED_VALUE"""),"Joanna Victorian") -> Joanna Victorian | B8: =IFERROR(__xludf.DUMMYFUNCTION("""COMPUTED_VALUE"""),"L2") -> L2 | C8: =IF(D8>0,"Yes","No") -> No | D8: 0
A9: =IFERROR(__xludf.DUMMYFUNCTION("""COMPUTED_VALUE"""),"Tatiana Lynn Carrion") -> Tatiana Lynn Carrion | B9: =IFERROR(__xludf.DUMMYFUNCTION("""COMPUTED_VALUE"""),"MS") -> MS | C9: =IF(D9>0,"Yes","No") -> No | D9: 0
A10: =IFERROR(__xludf.DUMMYFUNCTION("""COMPUTED_VALUE"""),"Alannah Brie Carrion") -> Alannah Brie Carrion | B10: =IFERROR(__xludf.DUMMYFUNCTION("""COMPUTED_VALUE"""),"L2") -> L2 | C10: =IF(D10>0,"Yes","No") -> No | D10: 0
A11: =IFERROR(__xludf.DUMMYFUNCTION("""COMPUTED_VALUE"""),"Diana Kostov") -> Diana Kostov | B11: =IFERROR(__xludf.DUMMYFUNCTION("""COMPUTED_VALUE"""),"L2") -> L2 | C11: =IF(D11>0,"Yes","No") -> No | D11: 0
A12: =IFERROR(__xludf.DUMMYFUNCTION("""COMPUTED_VALUE"""),"Shepherd Rogers Mora") -> Shepherd Rogers Mora | B12: =IFERROR(__xludf.DUMMYFUNCTION("""COMPUTED_VALUE"""),"L2") -> L2 | C12: =IF(D12>0,"Yes","No") -> No | D12: 0
A13: =IFERROR(__xludf.DUMMYFUNCTION("""COMPUTED_VALUE"""),"Airi Elliott") -> Airi Elliott | B13: =IFERROR(__xludf.DUMMYFUNCTION("""COMPUTED_VALUE"""),"L2") -> L2 | C13: =IF(D13>0,"Yes","No") -> No | D13: 0
A14: =IFERROR(__xludf.DUMMYFUNCTION("""COMPUTED_VALUE"""),"Alexander Wiebeck") -> Alexander Wiebeck | B14: =IFERROR(__xludf.DUMMYFUNCTION("""COMPUTED_VALUE"""),"L1") -> L1 | C14: =IF(D14>0,"Yes","No") -> No | D14: 0
A15: =IFERROR(__xludf.DUMMYFUNCTION("""COMPUTED_VALUE"""),"Lenora Lovell") -> Lenora Lovell | B15: =IFERROR(__xludf.DUMMYFUNCTION("""COMPUTED_VALUE"""),"L2") -> L2 | C15: =IF(D15>0,"Yes","No") -> No | D15: 0
A16: =IFERROR(__xludf.DUMMYFUNCTION("""COMPUTED_VALUE"""),"Jordan Boyer") -> Jordan Boyer | B16: =IFERROR(__xludf.DUMMYFUNCTION("""COMPUTED_VALUE"""),"L2") -> L2 | C16: =IF(D16>0,"Yes","No") -> No | D16: 0
A17: =IFERROR(__xludf.DUMMYFUNCTION("""COMPUTED_VALUE"""),"Alex Boyer") -> Alex Boyer | B17: =IFERROR(__xludf.DUMMYFUNCTION("""COMPUTED_VALUE"""),"L2") -> L2 | C17: =IF(D17>0,"Yes","No") -> No | D17: 0
A18: =IFERROR(__xludf.DUMMYFUNCTION("""COMPUTED_VALUE"""),"Kal Goodman") -> Kal Goodman | B18: =IFERROR(__xludf.DUMMYFUNCTION("""COMPUTED_VALUE"""),"LL") -> LL | C18: =IF(D18>0,"Yes","No") -> No | D18: 0
A19: =IFERROR(__xludf.DUMMYFUNCTION("""COMPUTED_VALUE"""),"Quinn Kirby") -> Quinn Kirby | B19: =IFERROR(__xludf.DUMMYFUNCTION("""COMPUTED_VALUE"""),"L2") -> L2 | C19: =IF(D19>0,"Yes","No") -> No | D19: 0
A20: =IFERROR(__xludf.DUMMYFUNCTION("""COMPUTED_VALUE"""),"Vera Carver") -> Vera Carver | B20: =IFERROR(__xludf.DUMMYFUNCTION("""COMPUTED_VALUE"""),"MS") -> MS | C20: =IF(D20>0,"Yes","No") -> No | D20: 0
A21: =IFERROR(__xludf.DUMMYFUNCTION("""COMPUTED_VALUE"""),"Alexander Schutt") -> Alexander Schutt | B21: =IFERROR(__xludf.DUMMYFUNCTION("""COMPUTED_VALUE"""),"L1") -> L1 | C21: =IF(D21>0,"Yes","No") -> No | D21: 0
A22: =IFERROR(__xludf.DUMMYFUNCTION("""COMPUTED_VALUE"""),"Joy Odunowo") -> Joy Odunowo | B22: =IFERROR(__xludf.DUMMYFUNCTION("""COMPUTED_VALUE"""),"MS") -> MS | C22: =IF(D22>0,"Yes","No") -> No | D22: 0
A23: =IFERROR(__xludf.DUMMYFUNCTION("""COMPUTED_VALUE"""),"Collin Keith") -> Collin Keith | B23: =IFERROR(__xludf.DUMMYFUNCTION("""COMPUTED_VALUE"""),"L2") -> L2 | C23: =IF(D23>0,"Yes","No") -> No | D23: 0
A24: =IFERROR(__xludf.DUMMYFUNCTION("""COMPUTED_VALUE"""),"Jameson Keith") -> Jameson Keith | B24: =IFERROR(__xludf.DUMMYFUNCTION("""COMPUTED_VALUE"""),"L1") -> L1 | C24: =IF(D24>0,"Yes","No") -> No | D24: 0
A25: =IFERROR(__xludf.DUMMYFUNCTION("""COMPUTED_VALUE"""),"Emma Mercer") -> Emma Mercer | B25: =IFERROR(__xludf.DUMMYFUNCTION("""COMPUTED_VALUE"""),"L1") -> L1 | C25: =IF(D25>0,"Yes","No") -> No | D25: 0
A26: =IFERROR(__xludf.DUMMYFUNCTION("""COMPUTED_VALUE"""),"Baltasar Andia") -> Baltasar Andia | B26: =IFERROR(__xludf.DUMMYFUNCTION("""COMPUTED_VALUE"""),"L2") -> L2 | C26: =IF(D26>0,"Yes","No") -> No | D26: 0
A27: =IFERROR(__xludf.DUMMYFUNCTION("""COMPUTED_VALUE"""),"Taysen Stoker") -> Taysen Stoker | B27: =IFERROR(__xludf.DUMMYFUNCTION("""COMPUTED_VALUE"""),"MS") -> MS | C27: =IF(D27>0,"Yes","No") -> No | D27: 0
A28: =IFERROR(__xludf.DUMMYFUNCTION("""COMPUTED_VALUE"""),"Sullavan Sutton") -> Sullavan Sutton | B28: =IFERROR(__xludf.DUMMYFUNCTION("""COMPUTED_VALUE"""),"MS") -> MS | C28: =IF(D28>0,"Yes","No") -> No | D28: 0
A29: =IFERROR(__xludf.DUMMYFUNCTION("""COMPUTED_VALUE"""),"Tanner Stoker") -> Tanner Stoker | B29: =IFERROR(__xludf.DUMMYFUNCTION("""COMPUTED_VALUE"""),"L2") -> L2 | C29: =IF(D29>0,"Yes","No") -> No | D29: 0
A30: =IFERROR(__xludf.DUMMYFUNCTION("""COMPUTED_VALUE"""),"Sawyer Sutton") -> Sawyer Sutton | B30: =IFERROR(__xludf.DUMMYFUNCTION("""COMPUTED_VALUE"""),"L2") -> L2 | C30: =IF(D30>0,"Yes","No") -> No | D30: 0
A31: =IFERROR(__xludf.DUMMYFUNCTION("""COMPUTED_VALUE"""),"Vaughn Stoker") -> Vaughn Stoker | B31: =IFERROR(__xludf.DUMMYFUNCTION("""COMPUTED_VALUE"""),"L1") -> L1 | C31: =IF(D31>0,"Yes","No") -> No | D31: 0
A32: =IFERROR(__xludf.DUMMYFUNCTION("""COMPUTED_VALUE"""),"Truett Sutton") -> Truett Sutton | B32: =IFERROR(__xludf.DUMMYFUNCTION("""COMPUTED_VALUE"""),"L1") -> L1 | C32: =IF(D32>0,"Yes","No") -> No | D32: 0
A33: =IFERROR(__xludf.DUMMYFUNCTION("""COMPUTED_VALUE"""),"Owen Lombard") -> Owen Lombard | B33: =IFERROR(__xludf.DUMMYFUNCTION("""COMPUTED_VALUE"""),"L2") -> L2 | C33: =IF(D33>0,"Yes","No") -> No | D33: 0
A34: =IFERROR(__xludf.DUMMYFUNCTION("""COMPUTED_VALUE"""),"Emma Ibarra") -> Emma Ibarra | B34: =IFERROR(__xludf.DUMMYFUNCTION("""COMPUTED_VALUE"""),"L1") -> L1 | C34: =IF(D34>0,"Yes","No") -> No | D34: 0
A35: =IFERROR(__xludf.DUMMYFUNCTION("""COMPUTED_VALUE"""),"Charles Scoma Johnson") -> Charles Scoma Johnson | B35: =IFERROR(__xludf.DUMMYFUNCTION("""COMPUTED_VALUE"""),"L2") -> L2 | C35: =IF(D35>0,"Yes","No") -> No | D35: 0
A36: =IFERROR(__xludf.DUMMYFUNCTION("""COMPUTED_VALUE"""),"Remi Dustin") -> Remi Dustin | B36: =IFERROR(__xludf.DUMMYFUNCTION("""COMPUTED_VALUE"""),"MS") -> MS | C36: =IF(D36>0,"Yes","No") -> No | D36: 0
A37: =IFERROR(__xludf.DUMMYFUNCTION("""COMPUTED_VALUE"""),"Reece Dustin") -> Reece Dustin | B37: =IFERROR(__xludf.DUMMYFUNCTION("""COMPUTED_VALUE"""),"MS") -> MS | C37: =IF(D37>0,"Yes","No") -> No | D37: 0
A38: =IFERROR(__xludf.DUMMYFUNCTION("""COMPUTED_VALUE"""),"L K") -> L K | B38: =IFERROR(__xludf.DUMMYFUNCTION("""COMPUTED_VALUE"""),"MS") -> MS | C38: =IF(D38>0,"Yes","No") -> No | D38: 0
A39: =IFERROR(__xludf.DUMMYFUNCTION("""COMPUTED_VALUE"""),"adria fuchs") -> adria fuchs | B39: =IFERROR(__xludf.DUMMYFUNCTION("""COMPUTED_VALUE"""),"L1") -> L1 | C39: =IF(D39>0,"Yes","No") -> No | D39: 0
A40: =IFERROR(__xludf.DUMMYFUNCTION("""COMPUTED_VALUE"""),"ari fuchs") -> ari fuchs | B40: =IFERROR(__xludf.DUMMYFUNCTION("""COMPUTED_VALUE"""),"MS") -> MS | C40: =IF(D40>0,"Yes","No") -> No | D40: 0
...

Sheet raw-20240814-20250309
A1: Level | B1: Student | C1: Date | D1: Subject | E1: App | F1: Course | G1: Anti-patterns | H1: Anti-pattern count | I1: Lessons mastered | J1: Essential Lessons Mastered | K1: Correct Questions | L1: Total Questions | M1: Accuracy | N1: Minutes
A2: L1 | B2: Logan Campbell | C2: 45723 | D2: Writing | E2: Alphawrite | H2: 0 | J2: 0 | N2: 0.029999999
A3: L1 | B3: Scotty Noel | C3: 45723 | D3: Writing | E3: Alphawrite | F3: Grade 4, Easy | G3: ANTI | Working on non-recommended skills | H3: 1 | I3: 0 | J3: 0 | K3: 16 | L3: 29 | M3: 0.55172414 | N3: 36.27
A4: L2 | B4: Blake Flores | C4: 45723 | D4: Writing | E4: Alphawrite | H4: 0 | J4: 0 | N4: 3.49
A5: L2 | B5: Connor Cason | C5: 45723 | D5: Writing | E5: Alphawrite | F5: Grade 3, Easy | G5: ANTI | Working on non-recommended skills | H5: 1 | I5: 0 | J5: 0 | K5: 6 | L5: 13 | M5: 0.46153846 | N5: 16.65
A6: L2 | B6: Ellen Meegan | C6: 45723 | D6: Writing | E6: Alphawrite | F6: Grade 5, Easy | G6: ANTI | Working on non-recommended skills | H6: 1 | I6: 0 | J6: 0 | K6: 2 | L6: 4 | M6: 0.5 | N6: 8.1899996
A7: L2 | B7: Kai Sticker | C7: 45723 | D7: Writing | E7: Alphawrite | F7: Grade 3, Medium | G7: ANTI | Working on non-recommended skills | H7: 1 | I7: 0 | J7: 0 | K7: 7 | L7: 7 | M7: 1 | N7: 3.9300001
A8: L2 | B8: Kai Sticker | C8: 45723 | D8: Writing | E8: Alphawrite | F8: Grade 4, Medium | G8: ANTI | Working on non-recommended skills | H8: 1 | I8: 0 | J8: 0 | K8: 0 | L8: 0 | N8: 0
A9: L2 | B9: Kai Sticker | C9: 45723 | D9: Writing | E9: Alphawrite | F9: Grade 5, Medium | G9: ANTI | Working on non-recommended skills | H9: 1 | I9: 0 | J9: 0 | K9: 0 | L9: 0 | N9: 0
A10: L2 | B10: Raegan Middleton | C10: 45723 | D10: Writing | E10: Alphawrite | H10: 0 | J10: 0 | N10: 0.02
A11: L2 | B11: Rocco Benetti | C11: 45723 | D11: Writing | E11: Alphawrite | F11: Grade 12, Medium | G11: ANTI | Working on non-recommended skills | H11: 1 | I11: 0 | J11: 0 | K11: 0 | L11: 2 | M11: 0 | N11: 18.6
A12: L2 | B12: Rocco Benetti | C12: 45723 | D12: Writing | E12: Alphawrite | F12: Grade 5, Easy | G12: ANTI | Working on non-recommended skills | H12: 1 | I12: 0 | J12: 0 | K12: 1 | L12: 1 | M12: 1 | N12: 0
A13: L2 | B13: Rocco Benetti | C13: 45723 | D13: Writing | E13: Alphawrite | F13: Grade 5, Hard | G13: ANTI | Working on non-recommended skills | H13: 1 | I13: 0 | J13: 0 | K13: 0 | L13: 1 | M13: 0 | N13: 0
A14: L2 | B14: Rocco Benetti | C14: 45723 | D14: Writing | E14: Alphawrite | F14: Grade 5, Medium | G14: ANTI | Working on non-recommended skills | H14: 1 | I14: 0 | J14: 0 | K14: 0 | L14: 1 | M14: 0 | N14: 0
A15: L1 | B15: Arjun Caberwal | C15: 45722 | D15: Writing | E15: Alphawrite | F15: Grade 4, Easy | H15: 0 | I15: 0 | J15: 0 | K15: 1 | L15: 3 | M15: 0.33333333 | N15: 3.55
A16: L1 | B16: Evelyn Gabler | C16: 45722 | D16: Writing | E16: Alphawrite | F16: Grade 4, Easy | H16: 0 | I16: 0 | J16: 0 | K16: 1 | L16: 3 | M16: 0.33333333 | N16: 15.07
A17: L1 | B17: Logan Campbell | C17: 45722 | D17: Writing | E17: Alphawrite | F17: Grade 4, Easy | H17: 0 | I17: 0 | J17: 0 | K17: 1 | L17: 1 | M17: 1 | N17: 4
A18: L1 | B18: Ramsey Levin | C18: 45722 | D18: Writing | E18: Alphawrite | F18: Grade 4, Easy | G18: ANTI | Working on non-recommended skills | H18: 1 | I18: 0 | J18: 0 | K18: 2 | L18: 2 | M18: 1 | N18: 9.29
A19: L1 | B19: Sarah Hunter | C19: 45722 | D19: Writing | E19: Alphawrite | F19: Grade 3, Easy | G19: POSI | Reading the question carefully before answering correctly | H19: 1 | I19: 0 | J19: 0 | K19: 11 | L19: 16 | M19: 0.6875 | N19: 15.52
A20: L2 | B20: Blake Flores | C20: 45722 | D20: Writing | E20: Alphawrite | F20: Grade 5, Easy | G20: ANTI | Working on non-recommended skills | H20: 1 | I20: 0 | J20: 0 | K20: 1 | L20: 4 | M20: 0.25 | N20: 7.8000002
A21: L2 | B21: Ellen Meegan | C21: 45722 | D21: Writing | E21: Alphawrite | F21: Grade 5, Easy | G21: ANTI | Working on non-recommended skills | H21: 1 | I21: 0 | J21: 0 | K21: 1 | L21: 10 | M21: 0.1 | N21: 13.19
A22: L2 | B22: Lavender Marrero | C22: 45722 | D22: Writing | E22: Alphawrite | F22: Grade 5, Easy | H22: 0 | I22: 0 | J22: 0 | K22: 0 | L22: 4 | M22: 0 | N22: 11.34
A23: L2 | B23: Lily Gray | C23: 45722 | D23: Writing | E23: Alphawrite | H23: 0 | J23: 0 | N23: 18.440001
A24: L2 | B24: Marcus Fuentes | C24: 45722 | D24: Writing | E24: Alphawrite | F24: Grade 3, Easy | H24: 0 | I24: 0 | J24: 0 | K24: 5 | L24: 7 | M24: 0.71428571 | N24: 13.61
A25: L2 | B25: Orion Campbell | C25: 45722 | D25: Writing | E25: Alphawrite | H25: 0 | J25: 0 | N25: 5.9000001
A26: L2 | B26: Raegan Middleton | C26: 45722 | D26: Writing | E26: Alphawrite | F26: Grade 3, Easy | H26: 0 | I26: 0 | J26: 0 | K26: 0 | L26: 9 | M26: 0 | N26: 16.129999
A27: L2 | B27: Rocco Benetti | C27: 45722 | D27: Writing | E27: Alphawrite | F27: Grade 12, Hard | G27: ANTI | Working on non-recommended skills | H27: 1 | I27: 0 | J27: 0 | K27: 0 | L27: 0 | N27: 0
A28: L2 | B28: Rocco Benetti | C28: 45722 | D28: Writing | E28: Alphawrite | F28: Grade 12, Medium | G28: ANTI | Working on non-recommended skills | H28: 1 | I28: 0 | J28: 0 | K28: 2 | L28: 3 | M28: 0.66666667 | N28: 0
A29: L2 | B29: Rocco Benetti | C29: 45722 | D29: Writing | E29: Alphawrite | F29: Grade 5, Easy | G29: ANTI | Working on non-recommended skills | H29: 1 | I29: 1 | J29: 0 | K29: 18 | L29: 25 | M29: 0.72 | N29: 27.049999
A30: L1 | B30: Arman Caberwal | C30: 45721 | D30: Writing | E30: Alphawrite | F30: Grade 4, Easy | G30: ANTI | Working on non-recommended skills | H30: 1 | I30: 0 | J30: 0 | K30: 7 | L30: 17 | M30: 0.41176471 | N30: 13.25
A31: L1 | B31: Brady York | C31: 45721 | D31: Writing | E31: Alphawrite | H31: 0 | J31: 0 | N31: 0.46000001
A32: L1 | B32: David Paul | C32: 45721 | D32: Writing | E32: Alphawrite | H32: 0 | J32: 0 | N32: 0.25
A33: L1 | B33: Jaxon Siers | C33: 45721 | D33: Writing | E33: Alphawrite | H33: 0 | J33: 0 | N33: 0.43000001
A34: L1 | B34: Marco Iorgulescu | C34: 45721 | D34: Writing | E34: Alphawrite | F34: Grade 3, Easy | H34: 0 | I34: 0 | J34: 0 | K34: 6 | L34: 8 | M34: 0.75 | N34: 13.11
A35: L1 | B35: Zane Rogers | C35: 45721 | D35: Writing | E35: Alphawrite | F35: Grade 4, Easy | H35: 0 | I35: 0 | J35: 0 | K35: 0 | L35: 0 | N35: 0
A36: L2 | B36: Archer Traff | C36: 45721 | D36: Writing | E36: Alphawrite | F36: Grade 5, Easy | H36: 0 | I36: 0 | J36: 0 | K36: 0 | L36: 0 | N36: 0.57999998
A37: L2 | B37: Blake Flores | C37: 45721 | D37: Writing | E37: Alphawrite | F37: Grade 5, Easy | H37: 0 | I37: 0 | J37: 0 | K37: 0 | L37: 1 | M37: 0 | N37: 3.2
A38: L2 | B38: Ellen Meegan | C38: 45721 | D38: Writing | E38: Alphawrite | F38: Grade 5, Easy | G38: ANTI | Working on non-recommended skills | H38: 1 | I38: 0 | J38: 0 | K38: 2 | L38: 4 | M38: 0.5 | N38: 8.7600002
A39: L2 | B39: Kai Sticker | C39: 45721 | D39: Writing | E39: Alphawrite | F39: Grade 12, Easy | G39: ANTI | Working on non-recommended skills | H39: 1 | I39: 0 | J39: 0 | K39: 0 | L39: 1 | M39: 0 | N39: 0
A40: L2 | B40: Kai Sticker | C40: 45721 | D40: Writing | E40: Alphawrite | F40: Grade 4, Hard | G40: ANTI | Working on non-recommended skills | H40: 1 | I40: 0 | J40: 0 | K40: 0 | L40: 1 | M40: 0 | N40: 0
...

Sheet add-20250310-26
A1: Level | B1: Student | C1: Date | D1: Subject | E1: App | F1: Course | G1: Anti-patterns | H1: Anti-pattern count | I1: Lessons mastered | J1: Essential Lessons Mastered | K1: Correct Questions | L1: Total Questions | M1: Accuracy | N1: Minutes | O1: Mastered at least 1 lesson? | P1: Spent time in the lesson? | Q1: Spent <30 min? | R1: Minutes per lesson mastered | U1: Average time taken to master 1 lesson
A2: L1 | B2: Alessandra Green | C2: 45742 | D2: Writing | E2: Alphawrite | F2: Grade 3, Easy | H2: 0 | I2: 1 | J2: 0 | K2: 30 | L2: 38 | M2: 0.78947368 | N2: 17.25 | O2: =IF(I2>0,"Yes","No") -> Yes | P2: =IF(N2>0,"Yes","No") -> Yes | Q2: =IF(N2<=30,"Yes","No") -> Yes | R2: =N2/I2 -> 17.25
A3: L1 | B3: Anaya Lenington | C3: 45742 | D3: Writing | E3: Alphawrite | H3: 0 | J3: 0 | N3: 0.02 | O3: =IF(I3>0,"Yes","No") -> No | P3: =IF(N3>0,"Yes","No") -> Yes | Q3: =IF(N3<=30,"Yes","No") -> Yes | R3: =N3/I3 -> #DIV/0!
A4: L1 | B4: Arjun Caberwal | C4: 45742 | D4: Writing | E4: Alphawrite | F4: Grade 4, Easy | H4: 0 | I4: 1 | J4: 0 | K4: 14 | L4: 20 | M4: 0.7 | N4: 7.77 | O4: =IF(I4>0,"Yes","No") -> Yes | P4: =IF(N4>0,"Yes","No") -> Yes | Q4: =IF(N4<=30,"Yes","No") -> Yes | R4: =N4/I4 -> 7.77
A5: L1 | B5: Arman Caberwal | C5: 45742 | D5: Writing | E5: Alphawrite | F5: Grade 4, Easy | H5: 0 | I5: 1 | J5: 0 | K5: 19 | L5: 19 | M5: 1 | N5: 12.51 | O5: =IF(I5>0,"Yes","No") -> Yes | P5: =IF(N5>0,"Yes","No") -> Yes | Q5: =IF(N5<=30,"Yes","No") -> Yes | R5: =N5/I5 -> 12.51
A6: L1 | B6: Brady York | C6: 45742 | D6: Writing | E6: Alphawrite | F6: Grade 3, Easy | H6: 0 | I6: 1 | J6: 0 | K6: 19 | L6: 27 | M6: 0.7037037 | N6: 12.46 | O6: =IF(I6>0,"Yes","No") -> Yes | P6: =IF(N6>0,"Yes","No") -> Yes | Q6: =IF(N6<=30,"Yes","No") -> Yes | R6: =N6/I6 -> 12.46
A7: L1 | B7: David Paul | C7: 45742 | D7: Writing | E7: Alphawrite | F7: Grade 3, Easy | H7: 0 | I7: 1 | J7: 0 | K7: 48 | L7: 77 | M7: 0.62337662 | N7: 49.119999 | O7: =IF(I7>0,"Yes","No") -> Yes | P7: =IF(N7>0,"Yes","No") -> Yes | Q7: =IF(N7<=30,"Yes","No") -> No | R7: =N7/I7 -> 49.119999
A8: L1 | B8: David Paul | C8: 45742 | D8: Writing | E8: Alphawrite | F8: Grade 4, Easy | H8: 0 | I8: 0 | J8: 0 | K8: 0 | L8: 2 | M8: 0 | N8: 0 | O8: =IF(I8>0,"Yes","No") -> No | P8: =IF(N8>0,"Yes","No") -> No | Q8: =IF(N8<=30,"Yes","No") -> Yes | R8: =N8/I8 -> #DIV/0!
A9: L1 | B9: Elaina Robertson | C9: 45742 | D9: Writing | E9: Alphawrite | F9: Grade 4, Easy | H9: 0 | I9: 1 | J9: 0 | K9: 12 | L9: 13 | M9: 0.92307692 | N9: 0 | O9: =IF(I9>0,"Yes","No") -> Yes | P9: =IF(N9>0,"Yes","No") -> No | Q9: =IF(N9<=30,"Yes","No") -> Yes | R9: =N9/I9 -> 0
A10: L1 | B10: Evelyn Gabler | C10: 45742 | D10: Writing | E10: Alphawrite | F10: Grade 4, Easy | H10: 0 | I10: 1 | J10: 0 | K10: 8 | L10: 8 | M10: 1 | N10: 8.0100002 | O10: =IF(I10>0,"Yes","No") -> Yes | P10: =IF(N10>0,"Yes","No") -> Yes | Q10: =IF(N10<=30,"Yes","No") -> Yes | R10: =N10/I10 -> 8.0100002
A11: L1 | B11: Evelyn Gabler | C11: 45742 | D11: Writing | E11: Alphawrite | F11: Grade 5, Easy | H11: 0 | I11: 0 | J11: 0 | K11: 0 | L11: 0 | N11: 0 | O11: =IF(I11>0,"Yes","No") -> No | P11: =IF(N11>0,"Yes","No") -> No | Q11: =IF(N11<=30,"Yes","No") -> Yes | R11: =N11/I11 -> #DIV/0!
A12: L1 | B12: Hazel Salton | C12: 45742 | D12: Writing | E12: Alphawrite | F12: Grade 3, Easy | H12: 0 | I12: 0 | J12: 0 | K12: 18 | L12: 26 | M12: 0.69230769 | N12: 11.88 | O12: =IF(I12>0,"Yes","No") -> No | P12: =IF(N12>0,"Yes","No") -> Yes | Q12: =IF(N12<=30,"Yes","No") -> Yes | R12: =N12/I12 -> #DIV/0! | Y12: Exclude instances of students spending >30 min (they may have left their laptops on without any action)
A13: L1 | B13: Hazel Salton | C13: 45742 | D13: Writing | E13: Alphawrite | F13: Grade 4, Easy | H13: 0 | I13: 0 | J13: 0 | K13: 0 | L13: 0 | N13: 0 | O13: =IF(I13>0,"Yes","No") -> No | P13: =IF(N13>0,"Yes","No") -> No | Q13: =IF(N13<=30,"Yes","No") -> Yes | R13: =N13/I13 -> #DIV/0!
A14: L1 | B14: Ian Mentgen | C14: 45742 | D14: Writing | E14: Alphawrite | F14: Grade 3, Easy | H14: 0 | I14: 1 | J14: 0 | K14: 14 | L14: 16 | M14: 0.875 | N14: 6.8000002 | O14: =IF(I14>0,"Yes","No") -> Yes | P14: =IF(N14>0,"Yes","No") -> Yes | Q14: =IF(N14<=30,"Yes","No") -> Yes | R14: =N14/I14 -> 6.8000002
A15: L1 | B15: Jaxon Siers | C15: 45742 | D15: Writing | E15: Alphawrite | F15: Grade 3, Easy | H15: 0 | I15: 2 | J15: 0 | K15: 36 | L15: 52 | M15: 0.69230769 | N15: 15.5 | O15: =IF(I15>0,"Yes","No") -> Yes | P15: =IF(N15>0,"Yes","No") -> Yes | Q15: =IF(N15<=30,"Yes","No") -> Yes | R15: =N15/I15 -> 7.75
A16: L1 | B16: Jaxon Siers | C16: 45742 | D16: Writing | E16: Alphawrite | F16: Grade 4, Easy | H16: 0 | I16: 0 | J16: 0 | K16: 0 | L16: 0 | N16: 0 | O16: =IF(I16>0,"Yes","No") -> No | P16: =IF(N16>0,"Yes","No") -> No | Q16: =IF(N16<=30,"Yes","No") -> Yes | R16: =N16/I16 -> #DIV/0!
A17: L1 | B17: Logan Campbell | C17: 45742 | D17: Writing | E17: Alphawrite | F17: Grade 4, Easy | H17: 0 | I17: 0 | J17: 0 | K17: 0 | L17: 0 | N17: 7.9299998 | O17: =IF(I17>0,"Yes","No") -> No | P17: =IF(N17>0,"Yes","No") -> Yes | Q17: =IF(N17<=30,"Yes","No") -> Yes | R17: =N17/I17 -> #DIV/0!
A18: L1 | B18: Max Vaughan | C18: 45742 | D18: Writing | E18: Alphawrite | F18: Grade 3, Easy | H18: 0 | I18: 1 | J18: 0 | K18: 12 | L18: 12 | M18: 1 | N18: 10.01 | O18: =IF(I18>0,"Yes","No") -> Yes | P18: =IF(N18>0,"Yes","No") -> Yes | Q18: =IF(N18<=30,"Yes","No") -> Yes | R18: =N18/I18 -> 10.01 | U18: Average accuracy for mastered lessons:
A19: L1 | B19: Omar Ibarra | C19: 45742 | D19: Writing | E19: Alphawrite | F19: Grade 4, Easy | H19: 0 | I19: 0 | J19: 0 | K19: 4 | L19: 10 | M19: 0.4 | N19: 9.5600004 | O19: =IF(I19>0,"Yes","No") -> No | P19: =IF(N19>0,"Yes","No") -> Yes | Q19: =IF(N19<=30,"Yes","No") -> Yes | R19: =N19/I19 -> #DIV/0!
A20: L1 | B20: Ramsey Levin | C20: 45742 | D20: Writing | E20: Alphawrite | F20: Grade 4, Easy | H20: 0 | I20: 0 | J20: 0 | K20: 2 | L20: 4 | M20: 0.5 | N20: 7.3600001 | O20: =IF(I20>0,"Yes","No") -> No | P20: =IF(N20>0,"Yes","No") -> Yes | Q20: =IF(N20<=30,"Yes","No") -> Yes | R20: =N20/I20 -> #DIV/0!
A21: L1 | B21: Sarah Hunter | C21: 45742 | D21: Writing | E21: Alphawrite | F21: Grade 3, Easy | H21: 0 | I21: 0 | J21: 0 | K21: 2 | L21: 4 | M21: 0.5 | N21: 3.78 | O21: =IF(I21>0,"Yes","No") -> No | P21: =IF(N21>0,"Yes","No") -> Yes | Q21: =IF(N21<=30,"Yes","No") -> Yes | R21: =N21/I21 -> #DIV/0!
A22: L1 | B22: Sophia Reicher | C22: 45742 | D22: Writing | E22: Alphawrite | F22: Grade 5, Easy | H22: 0 | I22: 0 | J22: 0 | K22: 4 | L22: 4 | M22: 1 | N22: 0 | O22: =IF(I22>0,"Yes","No") -> No | P22: =IF(N22>0,"Yes","No") -> No | Q22: =IF(N22<=30,"Yes","No") -> Yes | R22: =N22/I22 -> #DIV/0!
A23: L1 | B23: Tate Price | C23: 45742 | D23: Writing | E23: Alphawrite | F23: Grade 3, Easy | H23: 0 | I23: 0 | J23: 0 | K23: 0 | L23: 0 | N23: 0 | O23: =IF(I23>0,"Yes","No") -> No | P23: =IF(N23>0,"Yes","No") -> No | Q23: =IF(N23<=30,"Yes","No") -> Yes | R23: =N23/I23 -> #DIV/0!
A24: L1 | B24: Tate Price | C24: 45742 | D24: Writing | E24: Alphawrite | F24: Grade 5, Easy | H24: 0 | I24: 0 | J24: 0 | K24: 19 | L24: 29 | M24: 0.65517241 | N24: 7.23 | O24: =IF(I24>0,"Yes","No") -> No | P24: =IF(N24>0,"Yes","No") -> Yes | Q24: =IF(N24<=30,"Yes","No") -> Yes | R24: =N24/I24 -> #DIV/0!
A25: L2 | B25: Blake Flores | C25: 45742 | D25: Writing | E25: Alphawrite | F25: Grade 5, Easy | H25: 0 | I25: 0 | J25: 0 | K25: 2 | L25: 6 | M25: 0.33333333 | N25: 8.4499998 | O25: =IF(I25>0,"Yes","No") -> No | P25: =IF(N25>0,"Yes","No") -> Yes | Q25: =IF(N25<=30,"Yes","No") -> Yes | R25: =N25/I25 -> #DIV/0!
A26: L2 | B26: Connor Cason | C26: 45742 | D26: Writing | E26: Alphawrite | H26: 0 | J26: 0 | N26: 0.92000002 | O26: =IF(I26>0,"Yes","No") -> No | P26: =IF(N26>0,"Yes","No") -> Yes | Q26: =IF(N26<=30,"Yes","No") -> Yes | R26: =N26/I26 -> #DIV/0!
A27: L2 | B27: Helio Ortiz | C27: 45742 | D27: Writing | E27: Alphawrite | F27: Grade 3, Easy | H27: 0 | I27: 0 | J27: 0 | K27: 20 | L27: 49 | M27: 0.40816326 | N27: 42.18 | O27: =IF(I27>0,"Yes","No") -> No | P27: =IF(N27>0,"Yes","No") -> Yes | Q27: =IF(N27<=30,"Yes","No") -> No | R27: =N27/I27 -> #DIV/0!
A28: L2 | B28: Jack Bromberg | C28: 45742 | D28: Writing | E28: Alphawrite | H28: 0 | J28: 0 | N28: 0.02 | O28: =IF(I28>0,"Yes","No") -> No | P28: =IF(N28>0,"Yes","No") -> Yes | Q28: =IF(N28<=30,"Yes","No") -> Yes | R28: =N28/I28 -> #DIV/0! | Y28: Exclude instances of students spending >30 min (they may have left their laptops on without any action)
A29: L2 | B29: Jacob Atamas | C29: 45742 | D29: Writing | E29: Alphawrite | H29: 0 | J29: 0 | N29: 2.28 | O29: =IF(I29>0,"Yes","No") -> No | P29: =IF(N29>0,"Yes","No") -> Yes | Q29: =IF(N29<=30,"Yes","No") -> Yes | R29: =N29/I29 -> #DIV/0!
A30: L2 | B30: Lavender Marrero | C30: 45742 | D30: Writing | E30: Alphawrite | F30: Grade 4, Easy | H30: 0 | I30: 0 | J30: 0 | K30: 2 | L30: 6 | M30: 0.33333333 | N30: 7.0300002 | O30: =IF(I30>0,"Yes","No") -> No | P30: =IF(N30>0,"Yes","No") -> Yes | Q30: =IF(N30<=30,"Yes","No") -> Yes | R30: =N30/I30 -> #DIV/0!
A31: L2 | B31: Lily Gray | C31: 45742 | D31: Writing | E31: Alphawrite | F31: Grade 5, Easy | H31: 0 | I31: 0 | J31: 0 | K31: 0 | L31: 0 | N31: 6.5999999 | O31: =IF(I31>0,"Yes","No") -> No | P31: =IF(N31>0,"Yes","No") -> Yes | Q31: =IF(N31<=30,"Yes","No") -> Yes | R31: =N31/I31 -> #DIV/0!
A32: L2 | B32: Marcus Fuentes | C32: 45742 | D32: Writing | E32: Alphawrite | F32: Grade 3, Easy | H32: 0 | I32: 1 | J32: 0 | K32: 13 | L32: 17 | M32: 0.76470588 | N32: 6.6900001 | O32: =IF(I32>0,"Yes","No") -> Yes | P32: =IF(N32>0,"Yes","No") -> Yes | Q32: =IF(N32<=30,"Yes","No") -> Yes | R32: =N32/I32 -> 6.6900001
A33: L2 | B33: Mila Atamas | C33: 45742 | D33: Writing | E33: Alphawrite | F33: Grade 5, Easy | H33: 0 | I33: 0 | J33: 0 | K33: 16 | L33: 20 | M33: 0.8 | N33: 12.36 | O33: =IF(I33>0,"Yes","No") -> No | P33: =IF(N33>0,"Yes","No") -> Yes | Q33: =IF(N33<=30,"Yes","No") -> Yes | R33: =N33/I33 -> #DIV/0!
A34: L2 | B34: Orion Campbell | C34: 45742 | D34: Writing | E34: Alphawrite | F34: Grade 5, Easy | H34: 0 | I34: 0 | J34: 0 | K34: 0 | L34: 2 | M34: 0 | N34: 8.79 | O34: =IF(I34>0,"Yes","No") -> No | P34: =IF(N34>0,"Yes","No") -> Yes | Q34: =IF(N34<=30,"Yes","No") -> Yes | R34: =N34/I34 -> #DIV/0!
A35: L2 | B35: Raegan Middleton | C35: 45742 | D35: Writing | E35: Alphawrite | F35: Grade 3, Easy | H35: 0 | I35: 0 | J35: 0 | K35: 26 | L35: 28 | M35: 0.92857143 | N35: 7.21 | O35: =IF(I35>0,"Yes","No") -> No | P35: =IF(N35>0,"Yes","No") -> Yes | Q35: =IF(N35<=30,"Yes","No") -> Yes | R35: =N35/I35 -> #DIV/0!
A36: L2 | B36: Rocco Benetti | C36: 45742 | D36: Writing | E36: Alphawrite | F36: Grade 5, Easy | H36: 0 | I36: 2 | J36: 0 | K36: 47 | L36: 61 | M36: 0.7704918 | N36: 25.35 | O36: =IF(I36>0,"Yes","No") -> Yes | P36: =IF(N36>0,"Yes","No") -> Yes | Q36: =IF(N36<=30,"Yes","No") -> Yes | R36: =N36/I36 -> 12.675
A37: L2 | B37: Xavier Siddall | C37: 45742 | D37: Writing | E37: Alphawrite | F37: Grade 3, Easy | H37: 0 | I37: 0 | J37: 0 | K37: 23 | L37: 33 | M37: 0.6969697 | N37: 44.529999 | O37: =IF(I37>0,"Yes","No") -> No | P37: =IF(N37>0,"Yes","No") -> Yes | Q37: =IF(N37<=30,"Yes","No") -> No | R37: =N37/I37 -> #DIV/0!
A38: L1 | B38: Anaya Lenington | C38: 45741 | D38: Writing | E38: Alphawrite | F38: Grade 4, Easy | H38: 0 | I38: 1 | J38: 0 | K38: 16 | L38: 22 | M38: 0.72727273 | N38: 5.7199998 | O38: =IF(I38>0,"Yes","No") -> Yes | P38: =IF(N38>0,"Yes","No") -> Yes | Q38: =IF(N38<=30,"Yes","No") -> Yes | R38: =N38/I38 -> 5.7199998
A39: L1 | B39: Arjun Caberwal | C39: 45741 | D39: Writing | E39: Alphawrite | F39: Grade 4, Easy | H39: 0 | I39: 1 | J39: 0 | K39: 13 | L39: 19 | M39: 0.68421053 | N39: 0 | O39: =IF(I39>0,"Yes","No") -> Yes | P39: =IF(N39>0,"Yes","No") -> No | Q39: =IF(N39<=30,"Yes","No") -> Yes | R39: =N39/I39 -> 0
A40: L1 | B40: Arman Caberwal | C40: 45741 | D40: Writing | E40: Alphawrite | F40: Grade 4, Easy | H40: 0 | I40: 1 | J40: 0 | K40: 24 | L40: 38 | M40: 0.63157895 | N40: 12.41 | O40: =IF(I40>0,"Yes","No") -> Yes | P40: =IF(N40>0,"Yes","No") -> Yes | Q40: =IF(N40<=30,"Yes","No") -> Yes | R40: =N40/I40 -> 12.41
...

Sheet raw-aaa20250325
A1: Level | B1: Student | C1: Date | D1: Subject | E1: App | F1: Course | G1: Anti-patterns | H1: Anti-pattern count | I1: Lessons mastered | J1: Essential Lessons Mastered | K1: Correct Questions | L1: Total Questions | M1: Accuracy | N1: Minutes
A2: L1 | B2: Anaya Lenington | C2: 45741 | D2: Writing | E2: Alphawrite | F2: Grade 4, Easy | H2: 0 | I2: 1 | J2: 0 | K2: 16 | L2: 22 | M2: 0.72727273 | N2: 5.7199998
A3: L1 | B3: Arjun Caberwal | C3: 45741 | D3: Writing | E3: Alphawrite | F3: Grade 4, Easy | H3: 0 | I3: 1 | J3: 0 | K3: 13 | L3: 19 | M3: 0.68421053 | N3: 0
A4: L1 | B4: Arman Caberwal | C4: 45741 | D4: Writing | E4: Alphawrite | F4: Grade 4, Easy | H4: 0 | I4: 1 | J4: 0 | K4: 24 | L4: 38 | M4: 0.63157895 | N4: 12.41
A5: L1 | B5: Aubrey Curtis | C5: 45741 | D5: Writing | E5: Alphawrite | F5: Grade 4, Easy | H5: 0 | I5: 1 | J5: 0 | K5: 15 | L5: 25 | M5: 0.6 | N5: 0
A6: L1 | B6: Brady York | C6: 45741 | D6: Writing | E6: Alphawrite | F6: Grade 3, Easy | H6: 0 | I6: 1 | J6: 0 | K6: 15 | L6: 15 | M6: 1 | N6: 4
A7: L1 | B7: David Paul | C7: 45741 | D7: Writing | E7: Alphawrite | F7: Grade 3, Easy | H7: 0 | I7: 1 | J7: 0 | K7: 34 | L7: 59 | M7: 0.57627119 | N7: 8.2799997
A8: L1 | B8: Donnie Moore | C8: 45741 | D8: Writing | E8: Alphawrite | F8: Grade 3, Easy | H8: 0 | I8: 1 | J8: 0 | K8: 16 | L8: 16 | M8: 1 | N8: 0
A9: L1 | B9: Elaina Robertson | C9: 45741 | D9: Writing | E9: Alphawrite | F9: Grade 4, Easy | H9: 0 | I9: 1 | J9: 0 | K9: 58 | L9: 84 | M9: 0.69047619 | N9: 0
A10: L1 | B10: Evelyn Gabler | C10: 45741 | D10: Writing | E10: Alphawrite | F10: Grade 4, Easy | H10: 0 | I10: 1 | J10: 0 | K10: 50 | L10: 65 | M10: 0.76923077 | N10: 0
A11: L1 | B11: Evelyn Gabler | C11: 45741 | D11: Writing | E11: Alphawrite | F11: Grade 5, Easy | H11: 0 | I11: 0 | J11: 0 | K11: 0 | L11: 0 | N11: 0
A12: L1 | B12: Hazel Salton | C12: 45741 | D12: Writing | E12: Alphawrite | F12: Grade 3, Easy | H12: 0 | I12: 1 | J12: 0 | K12: 18 | L12: 36 | M12: 0.5 | N12: 0
A13: L1 | B13: Hazel Salton | C13: 45741 | D13: Writing | E13: Alphawrite | F13: Grade 4, Easy | H13: 0 | I13: 0 | J13: 0 | K13: 2 | L13: 4 | M13: 0.5 | N13: 0
A14: L1 | B14: Ian Mentgen | C14: 45741 | D14: Writing | E14: Alphawrite | F14: Grade 3, Easy | H14: 0 | I14: 1 | J14: 0 | K14: 30 | L14: 40 | M14: 0.75 | N14: 17.41
A15: L1 | B15: Jaxon Siers | C15: 45741 | D15: Writing | E15: Alphawrite | F15: Grade 3, Easy | H15: 0 | I15: 1 | J15: 0 | K15: 14 | L15: 18 | M15: 0.77777778 | N15: 25.790001
A16: L1 | B16: Jaxon Siers | C16: 45741 | D16: Writing | E16: Alphawrite | F16: Grade 4, Easy | H16: 0 | I16: 0 | J16: 0 | K16: 13 | L16: 17 | M16: 0.76470588 | N16: 0
A17: L1 | B17: Juan Diego Ortega | C17: 45741 | D17: Writing | E17: Alphawrite | H17: 0 | J17: 0 | N17: 3.45
A18: L1 | B18: Logan Campbell | C18: 45741 | D18: Writing | E18: Alphawrite | F18: Grade 4, Easy | H18: 0 | I18: 0 | J18: 0 | K18: 4 | L18: 6 | M18: 0.66666667 | N18: 0
A19: L1 | B19: Luna Montagna | C19: 45741 | D19: Writing | E19: Alphawrite | F19: Grade 3, Easy | H19: 0 | I19: 0 | J19: 0 | K19: 4 | L19: 9 | M19: 0.44444444 | N19: 0
A20: L1 | B20: Max Vaughan | C20: 45741 | D20: Writing | E20: Alphawrite | F20: Grade 3, Easy | H20: 0 | I20: 0 | J20: 0 | K20: 0 | L20: 2 | M20: 0 | N20: 0
A21: L1 | B21: Nate Evans | C21: 45741 | D21: Writing | E21: Edulastic | H21: 0 | J21: 0 | N21: 34.5
A22: L1 | B22: Ramsey Levin | C22: 45741 | D22: Writing | E22: Alphawrite | F22: Grade 4, Easy | H22: 0 | I22: 1 | J22: 0 | K22: 26 | L22: 29 | M22: 0.89655172 | N22: 0
A23: L1 | B23: Sarah Hunter | C23: 45741 | D23: Writing | E23: Alphawrite | F23: Grade 3, Easy | H23: 0 | I23: 2 | J23: 0 | K23: 43 | L23: 51 | M23: 0.84313726 | N23: 0
A24: L1 | B24: Sophia Reicher | C24: 45741 | D24: Writing | E24: Alphawrite | F24: Grade 5, Easy | H24: 0 | I24: 1 | J24: 0 | K24: 8 | L24: 10 | M24: 0.8 | N24: 2.8699999
A25: L1 | B25: Tate Price | C25: 45741 | D25: Writing | E25: Alphawrite | F25: Grade 5, Easy | H25: 0 | I25: 1 | J25: 0 | K25: 14 | L25: 14 | M25: 1 | N25: 0
A26: L2 | B26: Aksel Jensen | C26: 45741 | D26: Writing | E26: Alphawrite | H26: 0 | J26: 0 | N26: 0.050000001
A27: L2 | B27: Asha Nagar | C27: 45741 | D27: Writing | E27: Alphawrite | F27: Grade 5, Easy | H27: 0 | I27: 0 | J27: 0 | K27: 0 | L27: 0 | N27: 1.38
A28: L2 | B28: Bella Barba | C28: 45741 | D28: Writing | E28: Alphawrite | F28: Grade 5, Easy | H28: 0 | I28: 3 | J28: 0 | K28: 46 | L28: 64 | M28: 0.71875 | N28: 30.85
A29: L2 | B29: Blake Flores | C29: 45741 | D29: Writing | E29: Alphawrite | F29: Grade 4, Easy | H29: 0 | I29: 0 | J29: 0 | K29: 0 | L29: 0 | N29: 0
A30: L2 | B30: Blake Flores | C30: 45741 | D30: Writing | E30: Alphawrite | F30: Grade 5, Easy | H30: 0 | I30: 0 | J30: 0 | K30: 11 | L30: 13 | M30: 0.84615385 | N30: 0
A31: L2 | B31: Brooklyn Allred | C31: 45741 | D31: Writing | E31: Alphawrite | F31: Grade 4, Easy | H31: 0 | I31: 0 | J31: 0 | K31: 2 | L31: 4 | M31: 0.5 | N31: 2.51
A32: L2 | B32: Connor Cason | C32: 45741 | D32: Writing | E32: Alphawrite | F32: Grade 3, Easy | H32: 0 | I32: 0 | J32: 0 | K32: 6 | L32: 6 | M32: 1 | N32: 6.6100001
A33: L2 | B33: Connor Cason | C33: 45741 | D33: Writing | E33: Alphawrite | F33: Grade 4, Easy | H33: 0 | I33: 0 | J33: 0 | K33: 0 | L33: 0 | N33: 0
A34: L2 | B34: Elena Mentgen | C34: 45741 | D34: Writing | E34: Alphawrite | F34: Grade 3, Easy | H34: 0 | I34: 0 | J34: 0 | K34: 6 | L34: 6 | M34: 1 | N34: 0
A35: L2 | B35: Elena Mentgen | C35: 45741 | D35: Writing | E35: Alphawrite | F35: Grade 5, Easy | H35: 0 | I35: 2 | J35: 0 | K35: 36 | L35: 40 | M35: 0.9 | N35: 11.92
A36: L2 | B36: Jack Bromberg | C36: 45741 | D36: Writing | E36: Alphawrite | H36: 0 | J36: 0 | N36: 0.56
A37: L2 | B37: Jason Montagna | C37: 45741 | D37: Writing | E37: Alphawrite | F37: Grade 4, Easy | H37: 0 | I37: 0 | J37: 0 | K37: 14 | L37: 28 | M37: 0.5 | N37: 30.5
A38: L2 | B38: Kai Sticker | C38: 45741 | D38: Writing | E38: Alphawrite | F38: Grade 4, Easy | H38: 0 | I38: 0 | J38: 0 | K38: 2 | L38: 2 | M38: 1 | N38: 0
A39: L2 | B39: Kai Sticker | C39: 45741 | D39: Writing | E39: Alphawrite | F39: Grade 8, Easy | H39: 0 | I39: 1 | J39: 0 | K39: 24 | L39: 28 | M39: 0.85714286 | N39: 0
A40: L2 | B40: Krish Bhakta | C40: 45741 | D40: Writing | E40: Alphawrite | H40: 0 | J40: 0 | N40: 0.27000001
...

Sheet mastered-all
A1: student | B1: third_party_level_id | C1: app | D1: date | E1: activity_units_attempted | F1: activity_units_correct | G1: new grade | H1: new code
A2: Juan Diego Ortega | B2: 4.2.FRAGMENT_OR_SENTENCE | C2: Alphawrite | D2: 45746 | G2: =VLOOKUP(B2,'old-aw-skill-plan'!A:I,7,FALSE) -> 4 | H2: =VLOOKUP(B2,'old-aw-skill-plan'!A:I,9,FALSE) -> 4-1
A3: Juan Diego Ortega | B3: 4.2.MAKE_TOPIC_SENTENCES | C3: Alphawrite | D3: 45746 | G3: =VLOOKUP(B3,'old-aw-skill-plan'!A:I,7,FALSE) -> 7 | H3: =VLOOKUP(B3,'old-aw-skill-plan'!A:I,9,FALSE) -> 7-5
A4: Juan Diego Ortega | B4: 4.2.WRITE_SENTENCE_ABOUT_PICTURE | C4: Alphawrite | D4: 45746 | E4: 22 | F4: 16 | G4: =VLOOKUP(B4,'old-aw-skill-plan'!A:I,7,FALSE) -> 4 | H4: =VLOOKUP(B4,'old-aw-skill-plan'!A:I,9,FALSE) -> 4-6
A5: Elaina Robertson | B5: 4.2.FRAGMENT_OR_SENTENCE | C5: Alphawrite | D5: 45745 | E5: 15 | F5: 13 | G5: =VLOOKUP(B5,'old-aw-skill-plan'!A:I,7,FALSE) -> 4 | H5: =VLOOKUP(B5,'old-aw-skill-plan'!A:I,9,FALSE) -> 4-1
A6: Jaxon Siers | B6: 3.2.ELIMINATE_IRRELEVANT_SENTENCES | C6: Alphawrite | D6: 45745 | G6: =VLOOKUP(B6,'old-aw-skill-plan'!A:I,7,FALSE) -> 6 | H6: =VLOOKUP(B6,'old-aw-skill-plan'!A:I,9,FALSE) -> 6-4
A7: Jaxon Siers | B7: 3.2.FRAGMENT_OR_SENTENCE | C7: Alphawrite | D7: 45745 | G7: =VLOOKUP(B7,'old-aw-skill-plan'!A:I,7,FALSE) -> 3 | H7: =VLOOKUP(B7,'old-aw-skill-plan'!A:I,9,FALSE) -> 3-1
A8: Jaxon Siers | B8: 4.2.IDENTIFY_SENTENCE_TYPE | C8: Alphawrite | D8: 45745 | E8: 10 | F8: 10 | G8: =VLOOKUP(B8,'old-aw-skill-plan'!A:I,7,FALSE) -> 4 | H8: =VLOOKUP(B8,'old-aw-skill-plan'!A:I,9,FALSE) -> 4-3
A9: Juan Diego Ortega | B9: 4.2.WRITE_SENTENCE_ABOUT_PICTURE | C9: Alphawrite | D9: 45745 | E9: 4 | F9: 0 | G9: =VLOOKUP(B9,'old-aw-skill-plan'!A:I,7,FALSE) -> 4 | H9: =VLOOKUP(B9,'old-aw-skill-plan'!A:I,9,FALSE) -> 4-6
A10: Max Vaughan | B10: 3.2.CHANGE_SENTENCE_TYPE | C10: Alphawrite | D10: 45745 | E10: 14 | F10: 2 | G10: =VLOOKUP(B10,'old-aw-skill-plan'!A:I,7,FALSE) -> 3 | H10: =VLOOKUP(B10,'old-aw-skill-plan'!A:I,9,FALSE) -> 3-4
A11: Max Vaughan | B11: 3.2.FRAGMENT_OR_SENTENCE | C11: Alphawrite | D11: 45745 | E11: 10 | F11: 10 | G11: =VLOOKUP(B11,'old-aw-skill-plan'!A:I,7,FALSE) -> 3 | H11: =VLOOKUP(B11,'old-aw-skill-plan'!A:I,9,FALSE) -> 3-1
A12: Alessandra Green | B12: 3.2.FRAGMENT_OR_SENTENCE | C12: Alphawrite | D12: 45744 | E12: 18 | F12: 14 | G12: =VLOOKUP(B12,'old-aw-skill-plan'!A:I,7,FALSE) -> 3 | H12: =VLOOKUP(B12,'old-aw-skill-plan'!A:I,9,FALSE) -> 3-1
A13: Anaya Lenington | B13: 4.2.FRAGMENT_OR_SENTENCE | C13: Alphawrite | D13: 45744 | E13: 2 | F13: 0 | G13: =VLOOKUP(B13,'old-aw-skill-plan'!A:I,7,FALSE) -> 4 | H13: =VLOOKUP(B13,'old-aw-skill-plan'!A:I,9,FALSE) -> 4-1
A14: Anaya Lenington | B14: 4.2.UNSCRAMBLE_SENTENCES | C14: Alphawrite | D14: 45744 | E14: 16 | F14: 16 | G14: =VLOOKUP(B14,'old-aw-skill-plan'!A:I,7,FALSE) -> 4 | H14: =VLOOKUP(B14,'old-aw-skill-plan'!A:I,9,FALSE) -> 4-2
A15: Arjun Caberwal | B15: 4.2.IDENTIFY_SENTENCE_TYPE | C15: Alphawrite | D15: 45744 | E15: 14 | F15: 14 | G15: =VLOOKUP(B15,'old-aw-skill-plan'!A:I,7,FALSE) -> 4 | H15: =VLOOKUP(B15,'old-aw-skill-plan'!A:I,9,FALSE) -> 4-3
A16: Arman Caberwal | B16: 4.2.UNSCRAMBLE_SENTENCES | C16: Alphawrite | D16: 45744 | E16: 12 | F16: 12 | G16: =VLOOKUP(B16,'old-aw-skill-plan'!A:I,7,FALSE) -> 4 | H16: =VLOOKUP(B16,'old-aw-skill-plan'!A:I,9,FALSE) -> 4-2
A17: Asher Hazard | B17: 3.2.FRAGMENT_OR_SENTENCE | C17: Alphawrite | D17: 45744 | E17: 11 | F17: 6 | G17: =VLOOKUP(B17,'old-aw-skill-plan'!A:I,7,FALSE) -> 3 | H17: =VLOOKUP(B17,'old-aw-skill-plan'!A:I,9,FALSE) -> 3-1
A18: Asher Hazard | B18: 3.2.WRITE_SENTENCE_ABOUT_PICTURE | C18: Alphawrite | D18: 45744 | G18: =VLOOKUP(B18,'old-aw-skill-plan'!A:I,7,FALSE) -> 3 | H18: =VLOOKUP(B18,'old-aw-skill-plan'!A:I,9,FALSE) -> 3-6
A19: Bella Barba | B19: 5.2.CHANGE_SENTENCE_TYPE | C19: Alphawrite | D19: 45744 | E19: 57 | F19: 45 | G19: =VLOOKUP(B19,'old-aw-skill-plan'!A:I,7,FALSE) -> 5 | H19: =VLOOKUP(B19,'old-aw-skill-plan'!A:I,9,FALSE) -> 5-4
A20: Bennett Morris | B20: 5.2.FRAGMENT_OR_SENTENCE | C20: Alphawrite | D20: 45744 | E20: 39 | F20: 29 | G20: =VLOOKUP(B20,'old-aw-skill-plan'!A:I,7,FALSE) -> 5 | H20: =VLOOKUP(B20,'old-aw-skill-plan'!A:I,9,FALSE) -> 5-1
A21: Brady York | B21: 3.2.UNSCRAMBLE_SENTENCES | C21: Alphawrite | D21: 45744 | E21: 12 | F21: 12 | G21: =VLOOKUP(B21,'old-aw-skill-plan'!A:I,7,FALSE) -> 3 | H21: =VLOOKUP(B21,'old-aw-skill-plan'!A:I,9,FALSE) -> 3-2
A22: Connor Cason | B22: 3.2.FRAGMENT_OR_SENTENCE | C22: Alphawrite | D22: 45744 | G22: =VLOOKUP(B22,'old-aw-skill-plan'!A:I,7,FALSE) -> 3 | H22: =VLOOKUP(B22,'old-aw-skill-plan'!A:I,9,FALSE) -> 3-1
A23: David Paul | B23: 3.2.UNSCRAMBLE_SENTENCES | C23: Alphawrite | D23: 45744 | E23: 12 | F23: 12 | G23: =VLOOKUP(B23,'old-aw-skill-plan'!A:I,7,FALSE) -> 3 | H23: =VLOOKUP(B23,'old-aw-skill-plan'!A:I,9,FALSE) -> 3-2
A24: Elena Mentgen | B24: 3.2.COMBINE_SENTENCES | C24: Alphawrite | D24: 45744 | G24: =VLOOKUP(B24,'old-aw-skill-plan'!A:I,7,FALSE) -> 3 | H24: =VLOOKUP(B24,'old-aw-skill-plan'!A:I,9,FALSE) -> 3-9
A25: Elena Mentgen | B25: 3.2.IDENTIFY_APPOSITIVES | C25: Alphawrite | D25: 45744 | E25: 15 | F25: 13 | G25: =VLOOKUP(B25,'old-aw-skill-plan'!A:I,7,FALSE) -> 3 | H25: =VLOOKUP(B25,'old-aw-skill-plan'!A:I,9,FALSE) -> 3-7
A26: Elena Mentgen | B26: 3.2.WRITE_APPOSITIVES | C26: Alphawrite | D26: 45744 | E26: 32 | F26: 24 | G26: =VLOOKUP(B26,'old-aw-skill-plan'!A:I,7,FALSE) -> 3 | H26: =VLOOKUP(B26,'old-aw-skill-plan'!A:I,9,FALSE) -> 3-8
A27: Elena Mentgen | B27: 3.2.WRITE_SENTENCE_ABOUT_PICTURE | C27: Alphawrite | D27: 45744 | E27: 15 | F27: 13 | G27: =VLOOKUP(B27,'old-aw-skill-plan'!A:I,7,FALSE) -> 3 | H27: =VLOOKUP(B27,'old-aw-skill-plan'!A:I,9,FALSE) -> 3-6
A28: Ellen Meegan | B28: 5.2.FRAGMENT_OR_SENTENCE | C28: Alphawrite | D28: 45744 | G28: =VLOOKUP(B28,'old-aw-skill-plan'!A:I,7,FALSE) -> 5 | H28: =VLOOKUP(B28,'old-aw-skill-plan'!A:I,9,FALSE) -> 5-1
A29: Hazel Salton | B29: 3.2.IDENTIFY_SENTENCE_TYPE | C29: Alphawrite | D29: 45744 | E29: 16 | F29: 14 | G29: =VLOOKUP(B29,'old-aw-skill-plan'!A:I,7,FALSE) -> 3 | H29: =VLOOKUP(B29,'old-aw-skill-plan'!A:I,9,FALSE) -> 3-3
A30: Hazel Salton | B30: 3.2.WRITE_SENTENCE_ABOUT_PICTURE | C30: Alphawrite | D30: 45744 | E30: 7 | F30: 6 | G30: =VLOOKUP(B30,'old-aw-skill-plan'!A:I,7,FALSE) -> 3 | H30: =VLOOKUP(B30,'old-aw-skill-plan'!A:I,9,FALSE) -> 3-6
A31: Ian Mentgen | B31: 3.2.FRAGMENT_OR_SENTENCE | C31: Alphawrite | D31: 45744 | E31: 6 | F31: 0 | G31: =VLOOKUP(B31,'old-aw-skill-plan'!A:I,7,FALSE) -> 3 | H31: =VLOOKUP(B31,'old-aw-skill-plan'!A:I,9,FALSE) -> 3-1
A32: Jaiden Bhakta | B32: 5.2.CHANGE_SENTENCE_TYPE | C32: Alphawrite | D32: 45744 | E32: 14 | F32: 8 | G32: =VLOOKUP(B32,'old-aw-skill-plan'!A:I,7,FALSE) -> 5 | H32: =VLOOKUP(B32,'old-aw-skill-plan'!A:I,9,FALSE) -> 5-4
A33: Jaiden Bhakta | B33: 5.2.IDENTIFY_SENTENCE_TYPE | C33: Alphawrite | D33: 45744 | E33: 13 | F33: 13 | G33: =VLOOKUP(B33,'old-aw-skill-plan'!A:I,7,FALSE) -> 5 | H33: =VLOOKUP(B33,'old-aw-skill-plan'!A:I,9,FALSE) -> 5-3
A34: Jason Montagna | B34: 4.2.CHANGE_SENTENCE_TYPE | C34: Alphawrite | D34: 45744 | E34: 24 | F34: 16 | G34: =VLOOKUP(B34,'old-aw-skill-plan'!A:I,7,FALSE) -> 4 | H34: =VLOOKUP(B34,'old-aw-skill-plan'!A:I,9,FALSE) -> 4-4
A35: Jason Montagna | B35: 4.2.IDENTIFY_SENTENCE_TYPE | C35: Alphawrite | D35: 45744 | E35: 22 | F35: 18 | G35: =VLOOKUP(B35,'old-aw-skill-plan'!A:I,7,FALSE) -> 4 | H35: =VLOOKUP(B35,'old-aw-skill-plan'!A:I,9,FALSE) -> 4-3
A36: Jason Montagna | B36: 4.2.UNSCRAMBLE_SENTENCES | C36: Alphawrite | D36: 45744 | E36: 12 | F36: 10 | G36: =VLOOKUP(B36,'old-aw-skill-plan'!A:I,7,FALSE) -> 4 | H36: =VLOOKUP(B36,'old-aw-skill-plan'!A:I,9,FALSE) -> 4-2
A37: Jason Montagna | B37: 4.2.WRITE_SENTENCE_TYPE | C37: Alphawrite | D37: 45744 | G37: =VLOOKUP(B37,'old-aw-skill-plan'!A:I,7,FALSE) -> 4 | H37: =VLOOKUP(B37,'old-aw-skill-plan'!A:I,9,FALSE) -> 4-5
A38: Juan Diego Ortega | B38: 4.2.FRAGMENT_OR_SENTENCE | C38: Alphawrite | D38: 45744 | G38: =VLOOKUP(B38,'old-aw-skill-plan'!A:I,7,FALSE) -> 4 | H38: =VLOOKUP(B38,'old-aw-skill-plan'!A:I,9,FALSE) -> 4-1
A39: Juan Diego Ortega | B39: 4.2.WRITE_SENTENCE_ABOUT_PICTURE | C39: Alphawrite | D39: 45744 | E39: 31 | F39: 14 | G39: =VLOOKUP(B39,'old-aw-skill-plan'!A:I,7,FALSE) -> 4 | H39: =VLOOKUP(B39,'old-aw-skill-plan'!A:I,9,FALSE) -> 4-6
A40: Kai Sticker | B40: 4.2.TURN_PARAGRAPH_INTO_SPO | C40: Alphawrite | D40: 45744 | E40: 8 | F40: 6 | G40: =VLOOKUP(B40,'old-aw-skill-plan'!A:I,7,FALSE) -> 7 | H40: =VLOOKUP(B40,'old-aw-skill-plan'!A:I,9,FALSE) -> 7-7
...

Sheet new-aw-skill-plan 2025
A1: skill_id | B1: name | C1: QS_ID | D1: app | E1: order | F1: grade | G1: Course | H1: URL | I1: Activity Description
A2: alphawrite-sentences-i-fragment-or-sentence | B2: Fragment or Sentence? | C2: 3.2.FRAGMENT_OR_SENTENCE | D2: Alphawrite | E2: 1 | F2: 3 | G2: Sentences G3 | H2: https://alphawrite.alpha.school/practice/3/2/fragment-or-sentence | I2: Student task: Decide whether a word group is a complete sentence or a fragment; if it is a fragment, revise it into a complete sentence. Student produces: (1) a label—Sentence or Fragment—and (2) a corrected sentence when needed. Skills taught: identify subject + predicate (complete thought); fix fragments by adding missing subject/verb/idea; apply capitalization and end punctuation. Checks for correctness: corrected version expresses a complete thought, uses standard word order, and ends with correct punctuation.
A3: alphawrite-sentences-i-unscramble-sentences | B3: Unscramble Sentences | C3: 3.2.UNSCRAMBLE_SENTENCES | D3: Alphawrite | E3: 2 | F3: 3 | G3: Sentences G3 | H3: https://alphawrite.alpha.school/practice/3/2/unscramble-sentences | I3: Student task: Rearrange a set of jumbled words into a grammatical sentence. Student produces: one correctly ordered sentence with appropriate capitalization and end punctuation. Skills taught: English word order (subject–verb–object/modifiers); recognizing parts of speech; forming complete sentences; basic conventions. Checks for correctness: sentence reads naturally, includes a subject and verb, and uses correct capitalization/punctuation.
A4: alphawrite-sentences-i-identify-sentence-type | B4: Identify the Sentence Type | C4: 3.2.IDENTIFY_SENTENCE_TYPE | D4: Alphawrite | E4: 3 | F4: 3 | G4: Sentences G3 | H4: https://alphawrite.alpha.school/practice/3/2/identify-sentence-type | I4: Student task: Read a sentence and identify its type (declarative/statement, interrogative/question, imperative/command, or exclamatory/exclamation). Student produces: a label for the sentence type (and may justify using punctuation/purpose). Skills taught: connect sentence purpose to punctuation and structure; recognize question forms and commands; distinguish statement vs exclamation. Checks for correctness: chosen type matches the sentence’s purpose and punctuation (e.g., ? for questions, ! for exclamations).
A5: alphawrite-sentences-i-change-sentence-to-question | B5: Change Sentences into Questions | C5: 3.2.CHANGE_SENTENCE_INTO_QUESTION | D5: Alphawrite | E5: 4 | F5: 3 | G5: Sentences G3 | H5: https://alphawrite.alpha.school/practice/3/2/change-sentence-into-question | I5: Student task: Rewrite a statement (or another sentence type) as an interrogative sentence (a question). Student produces: one question that matches the original idea/topic and ends with a question mark. Skills taught: form questions (use question words or auxiliary verbs such as do/does/did when needed); adjust word order; punctuation. Checks for correctness: the revision is clearly a question, preserves the intended meaning, and uses correct capitalization and a question mark.
A6: alphawrite-sentences-i-change-sentence-type | B6: Change the Sentence Type | C6: 3.2.CHANGE_SENTENCE_TYPE | D6: Alphawrite | E6: 5 | F6: 3 | G6: Sentences G3 | H6: https://alphawrite.alpha.school/practice/3/2/change-sentence-type | I6: Student task: Rewrite a sentence as a different sentence type (e.g., turn a statement into a question or command) while keeping the core meaning/topic. Student produces: a revised sentence in the requested type with correct punctuation. Skills taught: manipulate sentence structure for purpose; use correct punctuation for each type; maintain meaning while revising. Checks for correctness: revised sentence matches the requested type (structure + punctuation) and still communicates the intended idea.
A7: alphawrite-sentences-i-use-sentence-types | B7: Write the Sentence Type | C7: 3.2.USE_SENTENCE_TYPES | D7: Alphawrite | E7: 6 | F7: 3 | G7: Sentences G3 | H7: https://alphawrite.alpha.school/practice/3/2/write-sentence-type | I7: Student task: Given a topic word/idea, write one example of each sentence type: statement, question, command, and exclamation. Student produces: four sentences, each correctly labeled or clearly showing its type. Skills taught: generate varied sentence types on purpose; control punctuation and structure; expand ideas within constraints. Checks for correctness: each sentence matches its type (purpose + punctuation) and is a complete, grammatically correct sentence.
A8: alphawrite-sentences-i-write-sentence-about-picture | B8: Write Questions About a Picture | C8: 3.2.WRITE_SENTENCE_ABOUT_PICTURE | D8: Alphawrite | E8: 7 | F8: 3 | G8: Sentences G3 | H8: https://alphawrite.alpha.school/practice/3/2/write-sentence-about-picture | I8: Student task: Examine a picture and generate thoughtful questions using question words (who/what/when/where/why/how). Student produces: one or more well-formed questions that relate to what is visible or implied in the image. Skills taught: question formation; observation and inference; using WH-words; capitalization and question marks. Checks for correctness: each question is grammatical, clearly refers to the image, and is punctuated correctly.
A9: alphawrite-sentences-i-basic-conjunctions | B9: Because, But, So | C9: 3.2.BASIC_CONJUNCTIONS | D9: Alphawrite | E9: 8 | F9: 3 | G9: Sentences G3 | H9: https://alphawrite.alpha.school/practice/3/2/basic-conjunctions | I9: Student task: Complete a sentence stem three different ways using the conjunctions because, but, and so. Student produces: three complete sentences: (1) cause/reason (because), (2) contrast/complication (but), (3) result/consequence (so). Skills taught: express logical relationships (cause, contrast, result); write complex/compound sentences; use commas appropriately with conjunctions. Checks for correctness: each conjunction creates the intended logical relationship and the sentence is complete and correctly punctuated.
A10: alphawrite-sentences-i-identify-appositives | B10: Identify Appositives | C10: 3.2.IDENTIFY_APPOSITIVES | D10: Alphawrite | E10: 9 | F10: 3 | G10: Sentences G3 | H10: https://alphawrite.alpha.school/practice/3/2/identify-appositives | I10: Student task: Find the appositive (a noun or noun phrase that renames another noun) in a sentence/short text and mark where commas should go. Student produces: the identified appositive and a corrected sentence with proper comma punctuation (if missing). Skills taught: recognize renaming phrases; punctuate nonessential appositives with commas; read for grammatical structure. Checks for correctness: appositive correctly renames a noun and commas accurately set it off when nonessential.
A11: alphawrite-sentences-i-write-appositives | B11: Write Appositives | C11: 3.2.WRITE_APPOSITIVES | D11: Alphawrite | E11: 10 | F11: 3 | G11: Sentences G3 | H11: https://alphawrite.alpha.school/practice/3/2/write-appositives | I11: Student task: Add an appositive phrase to a sentence to provide extra information about a noun. Student produces: an expanded sentence that includes a correctly punctuated appositive. Skills taught: sentence expansion for precision/detail; appositive structure; comma rules for nonessential information. Checks for correctness: appositive clearly renames the noun and commas (or no commas, if essential) are used correctly.
A12: alphawrite-sentences-i-subordinating-conjunctions | B12: Complete Subordinative Conjunctions | C12: 3.2.SUBORDINATING_CONJUNCTIONS | D12: Alphawrite | E12: 11 | F12: 3 | G12: Sentences G3 | H12: https://alphawrite.alpha.school/practice/3/2/subordinating-conjunctions | I12: Student task: Use a subordinating conjunction (e.g., although, since, when, because, if) to complete a sentence so it becomes a logical complex sentence. Student produces: a complete complex sentence with a dependent clause + independent clause. Skills taught: connect ideas with subordinate clauses; choose conjunctions that match meaning (time/cause/condition/contrast); comma rules for dependent clauses. Checks for correctness: sentence includes both clauses, meaning is logical, and punctuation is correct for the clause order.
A13: alphawrite-sentences-i-combine-sentences | B13: Combine Sentences | C13: 3.2.COMBINE_SENTENCES | D13: Alphawrite | E13: 12 | F13: 3 | G13: Sentences G3 | H13: https://alphawrite.alpha.school/practice/3/2/combine-sentences | I13: Student task: Combine two or more related sentences into one stronger sentence without losing meaning. Student produces: one combined sentence (often using conjunctions, embedding, or other combining techniques) with correct punctuation. Skills taught: sentence combining to show relationships; avoid run-ons and fragments; punctuation with conjunctions/clauses; vary sentence structure. Checks for correctness: combined sentence is grammatical, preserves all key information, and uses punctuation appropriately.
... A176: AW-COMPOSITIONS-G8 | B176: Essays G8 | C176: 8.2.POLISH | D176: Alphawrite | E176: 5 | F176: 8 | G176: Essays G8 | H176: alphawrite:compositions:essays-g8:essay-1-wynq:stage-polish:resource | I176: Student task: Edit the final draft for conventions and presentation. Student produces: a polished essay with corrected grammar, spelling, punctuation, and sentence-level errors. Skills taught: editing and proofreading; fix fragments/run-ons; vary sentence structure; apply standard conventions. Checks for correctness: writing is error-minimized, formatting is consistent, and sentences are clear and correct.

Sheet old-aw-skill-plan
A1: skill_id | B1: name | C1: app | D1: grade | E1: level | F1: code | G1: new grade | H1: order | I1: new code
A2: 3.2.FRAGMENT_OR_SENTENCE | B2: 3.2 Fragment or Sentence? | C2: Alphawrite | D2: 3 | E2: easy | F2: =LEFT(A2,3) -> 3.2 | G2: 3 | H2: 1 | I2: =CONCATENATE(G2,"-",H2) -> 3-1
A3: 3.2.UNSCRAMBLE_SENTENCES | B3: 3.2 Unscramble Sentences | C3: Alphawrite | D3: 3 | E3: easy | F3: =LEFT(A3,3) -> 3.2 | G3: 3 | H3: 2 | I3: =CONCATENATE(G3,"-",H3) -> 3-2
A4: 3.2.IDENTIFY_SENTENCE_TYPE | B4: 3.2 Identify the Sentence Type | C4: Alphawrite | D4: 3 | E4: easy | F4: =LEFT(A4,3) -> 3.2 | G4: 3 | H4: 3 | I4: =CONCATENATE(G4,"-",H4) -> 3-3
A5: 3.2.CHANGE_SENTENCE_TYPE | B5: 3.2 Change the Sentence Type | C5: Alphawrite | D5: 3 | E5: easy | F5: =LEFT(A5,3) -> 3.2 | G5: 3 | H5: 4 | I5: =CONCATENATE(G5,"-",H5) -> 3-4
A6: 3.2.WRITE_SENTENCE_TYPE | B6: 3.2 Write the Sentence Type | C6: Alphawrite | D6: 3 | E6: easy | F6: =LEFT(A6,3) -> 3.2 | G6: 3 | H6: 5 | I6: =CONCATENATE(G6,"-",H6) -> 3-5
A7: 3.2.WRITE_SENTENCE_ABOUT_PICTURE | B7: 3.2 Write Questions About a Picture | C7: Alphawrite | D7: 3 | E7: easy | F7: =LEFT(A7,3) -> 3.2 | G7: 3 | H7: 6 | I7: =CONCATENATE(G7,"-",H7) -> 3-6
A8: 3.2.IDENTIFY_APPOSITIVES | B8: 3.2 Identify Appositives | C8: Alphawrite | D8: 3 | E8: easy | F8: =LEFT(A8,3) -> 3.2 | G8: 3 | H8: 7 | I8: =CONCATENATE(G8,"-",H8) -> 3-7
